[2024-04-17T17:44:00.151+0000] {taskinstance.py:1979} INFO - Dependencies all met for dep_context=non-requeueable deps ti=<TaskInstance: files_ext.extract_data_from_csv manual__2024-04-17T17:33:49.035991+00:00 [queued]>
[2024-04-17T17:44:00.158+0000] {taskinstance.py:1979} INFO - Dependencies all met for dep_context=requeueable deps ti=<TaskInstance: files_ext.extract_data_from_csv manual__2024-04-17T17:33:49.035991+00:00 [queued]>
[2024-04-17T17:44:00.159+0000] {taskinstance.py:2193} INFO - Starting attempt 3 of 4
[2024-04-17T17:44:00.169+0000] {taskinstance.py:2217} INFO - Executing <Task(PythonOperator): extract_data_from_csv> on 2024-04-17 17:33:49.035991+00:00
[2024-04-17T17:44:00.176+0000] {standard_task_runner.py:60} INFO - Started process 1853 to run task
[2024-04-17T17:44:00.178+0000] {standard_task_runner.py:87} INFO - Running: ['***', 'tasks', 'run', 'files_ext', 'extract_data_from_csv', 'manual__2024-04-17T17:33:49.035991+00:00', '--job-id', '2135', '--raw', '--subdir', 'DAGS_FOLDER/files_extraction.py', '--cfg-path', '/tmp/tmpjqrp0tcx']
[2024-04-17T17:44:00.179+0000] {standard_task_runner.py:88} INFO - Job 2135: Subtask extract_data_from_csv
[2024-04-17T17:44:00.211+0000] {task_command.py:423} INFO - Running <TaskInstance: files_ext.extract_data_from_csv manual__2024-04-17T17:33:49.035991+00:00 [running]> on host fdd3cfdf3f53
[2024-04-17T17:44:00.272+0000] {taskinstance.py:2513} INFO - Exporting env vars: AIRFLOW_CTX_DAG_OWNER='***' AIRFLOW_CTX_DAG_ID='files_ext' AIRFLOW_CTX_TASK_ID='extract_data_from_csv' AIRFLOW_CTX_EXECUTION_DATE='2024-04-17T17:33:49.035991+00:00' AIRFLOW_CTX_TRY_NUMBER='3' AIRFLOW_CTX_DAG_RUN_ID='manual__2024-04-17T17:33:49.035991+00:00'
[2024-04-17T17:44:00.273+0000] {logging_mixin.py:188} INFO - /opt/***/dags/../extraction_done
[2024-04-17T17:44:00.274+0000] {logging_mixin.py:188} INFO - Directory already exists.
[2024-04-17T17:44:00.285+0000] {logging_mixin.py:188} INFO - An error occurred while moving file '/opt/***/dags/../data/vehicle-data.csv': [Errno 21] Is a directory: '/opt/***/dags/../extraction_done'
[2024-04-17T17:44:00.286+0000] {taskinstance.py:2731} ERROR - Task failed with exception
Traceback (most recent call last):
  File "/home/airflow/.local/lib/python3.8/site-packages/airflow/models/taskinstance.py", line 444, in _execute_task
    result = _execute_callable(context=context, **execute_callable_kwargs)
  File "/home/airflow/.local/lib/python3.8/site-packages/airflow/models/taskinstance.py", line 414, in _execute_callable
    return execute_callable(context=context, **execute_callable_kwargs)
  File "/home/airflow/.local/lib/python3.8/site-packages/airflow/operators/python.py", line 200, in execute
    return_value = self.execute_callable()
  File "/home/airflow/.local/lib/python3.8/site-packages/airflow/operators/python.py", line 217, in execute_callable
    return self.python_callable(*self.op_args, **self.op_kwargs)
  File "/opt/airflow/dags/files_extraction.py", line 255, in extract_data_from_csv
    shutil.move(file_path, extraction_done_folder)
  File "/usr/local/lib/python3.8/shutil.py", line 789, in move
    raise Error("Destination path '%s' already exists" % real_dst)
shutil.Error: Destination path '/opt/***/dags/../extraction_done/vehicle-data.csv' already exists
[2024-04-17T17:44:00.294+0000] {taskinstance.py:1149} INFO - Marking task as UP_FOR_RETRY. dag_id=files_ext, task_id=extract_data_from_csv, execution_date=20240417T173349, start_date=20240417T174400, end_date=20240417T174400
[2024-04-17T17:44:00.303+0000] {standard_task_runner.py:107} ERROR - Failed to execute job 2135 for task extract_data_from_csv (Destination path '/opt/***/dags/../extraction_done/vehicle-data.csv' already exists; 1853)
[2024-04-17T17:44:00.350+0000] {local_task_job_runner.py:234} INFO - Task exited with return code 1
[2024-04-17T17:44:00.368+0000] {taskinstance.py:3312} INFO - 0 downstream tasks scheduled from follow-on schedule check
