[2024-04-15T14:49:05.223+0000] {taskinstance.py:1979} INFO - Dependencies all met for dep_context=non-requeueable deps ti=<TaskInstance: files_ext.upload_to_s3 manual__2024-04-15T14:22:57.468504+00:00 [queued]>
[2024-04-15T14:49:05.250+0000] {taskinstance.py:1979} INFO - Dependencies all met for dep_context=requeueable deps ti=<TaskInstance: files_ext.upload_to_s3 manual__2024-04-15T14:22:57.468504+00:00 [queued]>
[2024-04-15T14:49:05.252+0000] {taskinstance.py:2193} INFO - Starting attempt 4 of 4
[2024-04-15T14:49:05.284+0000] {taskinstance.py:2217} INFO - Executing <Task(PythonOperator): upload_to_s3> on 2024-04-15 14:22:57.468504+00:00
[2024-04-15T14:49:05.306+0000] {standard_task_runner.py:60} INFO - Started process 3333 to run task
[2024-04-15T14:49:05.323+0000] {standard_task_runner.py:87} INFO - Running: ['***', 'tasks', 'run', 'files_ext', 'upload_to_s3', 'manual__2024-04-15T14:22:57.468504+00:00', '--job-id', '1842', '--raw', '--subdir', 'DAGS_FOLDER/files_extraction.py', '--cfg-path', '/tmp/tmp0f74w8qq']
[2024-04-15T14:49:05.332+0000] {standard_task_runner.py:88} INFO - Job 1842: Subtask upload_to_s3
[2024-04-15T14:49:05.467+0000] {task_command.py:423} INFO - Running <TaskInstance: files_ext.upload_to_s3 manual__2024-04-15T14:22:57.468504+00:00 [running]> on host fdd3cfdf3f53
[2024-04-15T14:49:05.636+0000] {taskinstance.py:2513} INFO - Exporting env vars: AIRFLOW_CTX_DAG_OWNER='***' AIRFLOW_CTX_DAG_ID='files_ext' AIRFLOW_CTX_TASK_ID='upload_to_s3' AIRFLOW_CTX_EXECUTION_DATE='2024-04-15T14:22:57.468504+00:00' AIRFLOW_CTX_TRY_NUMBER='4' AIRFLOW_CTX_DAG_RUN_ID='manual__2024-04-15T14:22:57.468504+00:00'
[2024-04-15T14:49:05.657+0000] {base.py:83} INFO - Using connection ID 'minin_s3' for task execution.
[2024-04-15T14:49:05.659+0000] {connection_wrapper.py:384} INFO - AWS Connection (conn_id='minin_s3', conn_type='aws') credentials retrieved from login and password.
[2024-04-15T14:49:05.660+0000] {warnings.py:109} WARNING - <string>:9: AirflowProviderDeprecationWarning: extra['host'] is deprecated and will be removed in a future release. Please set extra['endpoint_url'] instead

[2024-04-15T14:49:06.178+0000] {taskinstance.py:2731} ERROR - Task failed with exception
Traceback (most recent call last):
  File "/home/airflow/.local/lib/python3.8/site-packages/airflow/models/taskinstance.py", line 444, in _execute_task
    result = _execute_callable(context=context, **execute_callable_kwargs)
  File "/home/airflow/.local/lib/python3.8/site-packages/airflow/models/taskinstance.py", line 414, in _execute_callable
    return execute_callable(context=context, **execute_callable_kwargs)
  File "/home/airflow/.local/lib/python3.8/site-packages/airflow/operators/python.py", line 200, in execute
    return_value = self.execute_callable()
  File "/home/airflow/.local/lib/python3.8/site-packages/airflow/operators/python.py", line 217, in execute_callable
    return self.python_callable(*self.op_args, **self.op_kwargs)
  File "/opt/airflow/dags/files_extraction.py", line 34, in upload_to_s3
    s3_hook.load_file(
  File "/home/airflow/.local/lib/python3.8/site-packages/airflow/providers/amazon/aws/hooks/s3.py", line 137, in wrapper
    return func(*bound_args.args, **bound_args.kwargs)
  File "/home/airflow/.local/lib/python3.8/site-packages/airflow/providers/amazon/aws/hooks/s3.py", line 91, in wrapper
    return func(*bound_args.args, **bound_args.kwargs)
  File "/home/airflow/.local/lib/python3.8/site-packages/airflow/providers/amazon/aws/hooks/s3.py", line 1104, in load_file
    client.upload_file(filename, bucket_name, key, ExtraArgs=extra_args, Config=self.transfer_config)
  File "/home/airflow/.local/lib/python3.8/site-packages/boto3/s3/inject.py", line 145, in upload_file
    return transfer.upload_file(
  File "/home/airflow/.local/lib/python3.8/site-packages/boto3/s3/transfer.py", line 371, in upload_file
    future.result()
  File "/home/airflow/.local/lib/python3.8/site-packages/s3transfer/futures.py", line 103, in result
    return self._coordinator.result()
  File "/home/airflow/.local/lib/python3.8/site-packages/s3transfer/futures.py", line 266, in result
    raise self._exception
  File "/home/airflow/.local/lib/python3.8/site-packages/s3transfer/tasks.py", line 269, in _main
    self._submit(transfer_future=transfer_future, **kwargs)
  File "/home/airflow/.local/lib/python3.8/site-packages/s3transfer/upload.py", line 591, in _submit
    upload_input_manager.provide_transfer_size(transfer_future)
  File "/home/airflow/.local/lib/python3.8/site-packages/s3transfer/upload.py", line 244, in provide_transfer_size
    self._osutil.get_file_size(transfer_future.meta.call_args.fileobj)
  File "/home/airflow/.local/lib/python3.8/site-packages/s3transfer/utils.py", line 251, in get_file_size
    return os.path.getsize(filename)
  File "/usr/local/lib/python3.8/genericpath.py", line 50, in getsize
    return os.stat(filename).st_size
FileNotFoundError: [Errno 2] No such file or directory: 'tolldata.tgz'
[2024-04-15T14:49:06.196+0000] {taskinstance.py:1149} INFO - Marking task as FAILED. dag_id=files_ext, task_id=upload_to_s3, execution_date=20240415T142257, start_date=20240415T144905, end_date=20240415T144906
[2024-04-15T14:49:06.217+0000] {standard_task_runner.py:107} ERROR - Failed to execute job 1842 for task upload_to_s3 ([Errno 2] No such file or directory: 'tolldata.tgz'; 3333)
[2024-04-15T14:49:06.256+0000] {local_task_job_runner.py:234} INFO - Task exited with return code 1
[2024-04-15T14:49:06.275+0000] {taskinstance.py:3312} INFO - 0 downstream tasks scheduled from follow-on schedule check
