[2024-04-15T14:49:20.221+0000] {taskinstance.py:1979} INFO - Dependencies all met for dep_context=non-requeueable deps ti=<TaskInstance: files_ext.upload_to_s3 manual__2024-04-15T14:49:18.793713+00:00 [queued]>
[2024-04-15T14:49:20.234+0000] {taskinstance.py:1979} INFO - Dependencies all met for dep_context=requeueable deps ti=<TaskInstance: files_ext.upload_to_s3 manual__2024-04-15T14:49:18.793713+00:00 [queued]>
[2024-04-15T14:49:20.235+0000] {taskinstance.py:2193} INFO - Starting attempt 1 of 4
[2024-04-15T14:49:20.255+0000] {taskinstance.py:2217} INFO - Executing <Task(PythonOperator): upload_to_s3> on 2024-04-15 14:49:18.793713+00:00
[2024-04-15T14:49:20.265+0000] {standard_task_runner.py:60} INFO - Started process 3359 to run task
[2024-04-15T14:49:20.269+0000] {standard_task_runner.py:87} INFO - Running: ['***', 'tasks', 'run', 'files_ext', 'upload_to_s3', 'manual__2024-04-15T14:49:18.793713+00:00', '--job-id', '1850', '--raw', '--subdir', 'DAGS_FOLDER/files_extraction.py', '--cfg-path', '/tmp/tmpd0qmha9s']
[2024-04-15T14:49:20.273+0000] {standard_task_runner.py:88} INFO - Job 1850: Subtask upload_to_s3
[2024-04-15T14:49:20.337+0000] {task_command.py:423} INFO - Running <TaskInstance: files_ext.upload_to_s3 manual__2024-04-15T14:49:18.793713+00:00 [running]> on host fdd3cfdf3f53
[2024-04-15T14:49:20.442+0000] {taskinstance.py:2513} INFO - Exporting env vars: AIRFLOW_CTX_DAG_OWNER='***' AIRFLOW_CTX_DAG_ID='files_ext' AIRFLOW_CTX_TASK_ID='upload_to_s3' AIRFLOW_CTX_EXECUTION_DATE='2024-04-15T14:49:18.793713+00:00' AIRFLOW_CTX_TRY_NUMBER='1' AIRFLOW_CTX_DAG_RUN_ID='manual__2024-04-15T14:49:18.793713+00:00'
[2024-04-15T14:49:20.457+0000] {base.py:83} INFO - Using connection ID 'minin_s3' for task execution.
[2024-04-15T14:49:20.459+0000] {connection_wrapper.py:384} INFO - AWS Connection (conn_id='minin_s3', conn_type='aws') credentials retrieved from login and password.
[2024-04-15T14:49:20.460+0000] {warnings.py:109} WARNING - <string>:9: AirflowProviderDeprecationWarning: extra['host'] is deprecated and will be removed in a future release. Please set extra['endpoint_url'] instead

[2024-04-15T14:49:20.898+0000] {taskinstance.py:2731} ERROR - Task failed with exception
Traceback (most recent call last):
  File "/home/airflow/.local/lib/python3.8/site-packages/boto3/s3/transfer.py", line 371, in upload_file
    future.result()
  File "/home/airflow/.local/lib/python3.8/site-packages/s3transfer/futures.py", line 103, in result
    return self._coordinator.result()
  File "/home/airflow/.local/lib/python3.8/site-packages/s3transfer/futures.py", line 266, in result
    raise self._exception
  File "/home/airflow/.local/lib/python3.8/site-packages/s3transfer/tasks.py", line 139, in __call__
    return self._execute_main(kwargs)
  File "/home/airflow/.local/lib/python3.8/site-packages/s3transfer/tasks.py", line 162, in _execute_main
    return_value = self._main(**kwargs)
  File "/home/airflow/.local/lib/python3.8/site-packages/s3transfer/upload.py", line 764, in _main
    client.put_object(Bucket=bucket, Key=key, Body=body, **extra_args)
  File "/home/airflow/.local/lib/python3.8/site-packages/botocore/client.py", line 553, in _api_call
    return self._make_api_call(operation_name, kwargs)
  File "/home/airflow/.local/lib/python3.8/site-packages/botocore/client.py", line 1009, in _make_api_call
    raise error_class(parsed_response, operation_name)
botocore.errorfactory.NoSuchBucket: An error occurred (NoSuchBucket) when calling the PutObject operation: The specified bucket does not exist

During handling of the above exception, another exception occurred:

Traceback (most recent call last):
  File "/home/airflow/.local/lib/python3.8/site-packages/airflow/models/taskinstance.py", line 444, in _execute_task
    result = _execute_callable(context=context, **execute_callable_kwargs)
  File "/home/airflow/.local/lib/python3.8/site-packages/airflow/models/taskinstance.py", line 414, in _execute_callable
    return execute_callable(context=context, **execute_callable_kwargs)
  File "/home/airflow/.local/lib/python3.8/site-packages/airflow/operators/python.py", line 200, in execute
    return_value = self.execute_callable()
  File "/home/airflow/.local/lib/python3.8/site-packages/airflow/operators/python.py", line 217, in execute_callable
    return self.python_callable(*self.op_args, **self.op_kwargs)
  File "/opt/airflow/dags/files_extraction.py", line 34, in upload_to_s3
    s3_hook.load_file(
  File "/home/airflow/.local/lib/python3.8/site-packages/airflow/providers/amazon/aws/hooks/s3.py", line 137, in wrapper
    return func(*bound_args.args, **bound_args.kwargs)
  File "/home/airflow/.local/lib/python3.8/site-packages/airflow/providers/amazon/aws/hooks/s3.py", line 91, in wrapper
    return func(*bound_args.args, **bound_args.kwargs)
  File "/home/airflow/.local/lib/python3.8/site-packages/airflow/providers/amazon/aws/hooks/s3.py", line 1104, in load_file
    client.upload_file(filename, bucket_name, key, ExtraArgs=extra_args, Config=self.transfer_config)
  File "/home/airflow/.local/lib/python3.8/site-packages/boto3/s3/inject.py", line 145, in upload_file
    return transfer.upload_file(
  File "/home/airflow/.local/lib/python3.8/site-packages/boto3/s3/transfer.py", line 377, in upload_file
    raise S3UploadFailedError(
boto3.exceptions.S3UploadFailedError: Failed to upload dags/tolldata.tgz to volume/orders/tolldata.tgz: An error occurred (NoSuchBucket) when calling the PutObject operation: The specified bucket does not exist
[2024-04-15T14:49:20.908+0000] {taskinstance.py:1149} INFO - Marking task as UP_FOR_RETRY. dag_id=files_ext, task_id=upload_to_s3, execution_date=20240415T144918, start_date=20240415T144920, end_date=20240415T144920
[2024-04-15T14:49:20.919+0000] {standard_task_runner.py:107} ERROR - Failed to execute job 1850 for task upload_to_s3 (Failed to upload dags/tolldata.tgz to volume/orders/tolldata.tgz: An error occurred (NoSuchBucket) when calling the PutObject operation: The specified bucket does not exist; 3359)
[2024-04-15T14:49:20.965+0000] {local_task_job_runner.py:234} INFO - Task exited with return code 1
[2024-04-15T14:49:20.980+0000] {taskinstance.py:3312} INFO - 0 downstream tasks scheduled from follow-on schedule check
