[2024-04-02T03:49:22.385+0000] {taskinstance.py:1979} INFO - Dependencies all met for dep_context=non-requeueable deps ti=<TaskInstance: first_dag_pythonop.details manual__2024-04-02T03:49:17.855274+00:00 [queued]>
[2024-04-02T03:49:22.404+0000] {taskinstance.py:1979} INFO - Dependencies all met for dep_context=requeueable deps ti=<TaskInstance: first_dag_pythonop.details manual__2024-04-02T03:49:17.855274+00:00 [queued]>
[2024-04-02T03:49:22.405+0000] {taskinstance.py:2193} INFO - Starting attempt 1 of 4
[2024-04-02T03:49:22.435+0000] {taskinstance.py:2217} INFO - Executing <Task(PythonOperator): details> on 2024-04-02 03:49:17.855274+00:00
[2024-04-02T03:49:22.445+0000] {standard_task_runner.py:60} INFO - Started process 1650 to run task
[2024-04-02T03:49:22.448+0000] {standard_task_runner.py:87} INFO - Running: ['***', 'tasks', 'run', 'first_dag_pythonop', 'details', 'manual__2024-04-02T03:49:17.855274+00:00', '--job-id', '104', '--raw', '--subdir', 'DAGS_FOLDER/first_day_pythonop.py', '--cfg-path', '/tmp/tmp5i7jv0gf']
[2024-04-02T03:49:22.451+0000] {standard_task_runner.py:88} INFO - Job 104: Subtask details
[2024-04-02T03:49:22.534+0000] {task_command.py:423} INFO - Running <TaskInstance: first_dag_pythonop.details manual__2024-04-02T03:49:17.855274+00:00 [running]> on host 5c9eefa8eb82
[2024-04-02T03:49:22.699+0000] {taskinstance.py:2513} INFO - Exporting env vars: AIRFLOW_CTX_DAG_OWNER='***' AIRFLOW_CTX_DAG_ID='first_dag_pythonop' AIRFLOW_CTX_TASK_ID='details' AIRFLOW_CTX_EXECUTION_DATE='2024-04-02T03:49:17.855274+00:00' AIRFLOW_CTX_TRY_NUMBER='1' AIRFLOW_CTX_DAG_RUN_ID='manual__2024-04-02T03:49:17.855274+00:00'
[2024-04-02T03:49:22.702+0000] {taskinstance.py:2731} ERROR - Task failed with exception
Traceback (most recent call last):
  File "/home/airflow/.local/lib/python3.8/site-packages/airflow/models/taskinstance.py", line 444, in _execute_task
    result = _execute_callable(context=context, **execute_callable_kwargs)
  File "/home/airflow/.local/lib/python3.8/site-packages/airflow/models/taskinstance.py", line 414, in _execute_callable
    return execute_callable(context=context, **execute_callable_kwargs)
  File "/home/airflow/.local/lib/python3.8/site-packages/airflow/operators/python.py", line 200, in execute
    return_value = self.execute_callable()
  File "/home/airflow/.local/lib/python3.8/site-packages/airflow/operators/python.py", line 217, in execute_callable
    return self.python_callable(*self.op_args, **self.op_kwargs)
  File "/opt/airflow/dags/first_day_pythonop.py", line 29, in details
    name=ti.xcom.pull(task_ids="name")
AttributeError: 'TaskInstance' object has no attribute 'xcom'
[2024-04-02T03:49:22.724+0000] {taskinstance.py:1149} INFO - Marking task as UP_FOR_RETRY. dag_id=first_dag_pythonop, task_id=details, execution_date=20240402T034917, start_date=20240402T034922, end_date=20240402T034922
[2024-04-02T03:49:22.745+0000] {standard_task_runner.py:107} ERROR - Failed to execute job 104 for task details ('TaskInstance' object has no attribute 'xcom'; 1650)
[2024-04-02T03:49:22.783+0000] {local_task_job_runner.py:234} INFO - Task exited with return code 1
[2024-04-02T03:49:22.815+0000] {taskinstance.py:3312} INFO - 0 downstream tasks scheduled from follow-on schedule check
