[2024-04-15T12:13:50.881+0000] {taskinstance.py:1979} INFO - Dependencies all met for dep_context=non-requeueable deps ti=<TaskInstance: etl_data.combine_files manual__2024-04-15T12:13:48.859474+00:00 [queued]>
[2024-04-15T12:13:50.891+0000] {taskinstance.py:1979} INFO - Dependencies all met for dep_context=requeueable deps ti=<TaskInstance: etl_data.combine_files manual__2024-04-15T12:13:48.859474+00:00 [queued]>
[2024-04-15T12:13:50.892+0000] {taskinstance.py:2193} INFO - Starting attempt 1 of 4
[2024-04-15T12:13:50.907+0000] {taskinstance.py:2217} INFO - Executing <Task(BashOperator): combine_files> on 2024-04-15 12:13:48.859474+00:00
[2024-04-15T12:13:50.915+0000] {standard_task_runner.py:60} INFO - Started process 827 to run task
[2024-04-15T12:13:50.918+0000] {standard_task_runner.py:87} INFO - Running: ['***', 'tasks', 'run', 'etl_data', 'combine_files', 'manual__2024-04-15T12:13:48.859474+00:00', '--job-id', '1696', '--raw', '--subdir', 'DAGS_FOLDER/etl_data.py', '--cfg-path', '/tmp/tmp2iiv6wej']
[2024-04-15T12:13:50.920+0000] {standard_task_runner.py:88} INFO - Job 1696: Subtask combine_files
[2024-04-15T12:13:50.962+0000] {task_command.py:423} INFO - Running <TaskInstance: etl_data.combine_files manual__2024-04-15T12:13:48.859474+00:00 [running]> on host fdd3cfdf3f53
[2024-04-15T12:13:51.030+0000] {taskinstance.py:2513} INFO - Exporting env vars: AIRFLOW_CTX_DAG_OWNER='***' AIRFLOW_CTX_DAG_ID='etl_data' AIRFLOW_CTX_TASK_ID='combine_files' AIRFLOW_CTX_EXECUTION_DATE='2024-04-15T12:13:48.859474+00:00' AIRFLOW_CTX_TRY_NUMBER='1' AIRFLOW_CTX_DAG_RUN_ID='manual__2024-04-15T12:13:48.859474+00:00'
[2024-04-15T12:13:51.032+0000] {subprocess.py:63} INFO - Tmp dir root location: /tmp
[2024-04-15T12:13:51.033+0000] {subprocess.py:75} INFO - Running command: ['/usr/bin/bash', '-c', 'cat ../destination/csv_data.csv ../destination/tsv_data.csv ../destination/txt_data.csv > ../destination/combined_data.csv']
[2024-04-15T12:13:51.046+0000] {subprocess.py:86} INFO - Output:
[2024-04-15T12:13:51.049+0000] {subprocess.py:93} INFO - /usr/bin/bash: line 1: ../destination/combined_data.csv: No such file or directory
[2024-04-15T12:13:51.050+0000] {subprocess.py:97} INFO - Command exited with return code 1
[2024-04-15T12:13:51.069+0000] {taskinstance.py:2731} ERROR - Task failed with exception
Traceback (most recent call last):
  File "/home/airflow/.local/lib/python3.8/site-packages/airflow/models/taskinstance.py", line 444, in _execute_task
    result = _execute_callable(context=context, **execute_callable_kwargs)
  File "/home/airflow/.local/lib/python3.8/site-packages/airflow/models/taskinstance.py", line 414, in _execute_callable
    return execute_callable(context=context, **execute_callable_kwargs)
  File "/home/airflow/.local/lib/python3.8/site-packages/airflow/operators/bash.py", line 212, in execute
    raise AirflowException(
airflow.exceptions.AirflowException: Bash command failed. The command returned a non-zero exit code 1.
[2024-04-15T12:13:51.074+0000] {taskinstance.py:1149} INFO - Marking task as UP_FOR_RETRY. dag_id=etl_data, task_id=combine_files, execution_date=20240415T121348, start_date=20240415T121350, end_date=20240415T121351
[2024-04-15T12:13:51.528+0000] {standard_task_runner.py:107} ERROR - Failed to execute job 1696 for task combine_files (Bash command failed. The command returned a non-zero exit code 1.; 827)
[2024-04-15T12:13:51.573+0000] {local_task_job_runner.py:234} INFO - Task exited with return code 1
[2024-04-15T12:13:51.603+0000] {taskinstance.py:3312} INFO - 0 downstream tasks scheduled from follow-on schedule check
