[2024-04-17T17:36:47.118+0000] {taskinstance.py:1979} INFO - Dependencies all met for dep_context=non-requeueable deps ti=<TaskInstance: files_ext.extract_data_from_csv manual__2024-04-17T17:31:37.009298+00:00 [queued]>
[2024-04-17T17:36:47.125+0000] {taskinstance.py:1979} INFO - Dependencies all met for dep_context=requeueable deps ti=<TaskInstance: files_ext.extract_data_from_csv manual__2024-04-17T17:31:37.009298+00:00 [queued]>
[2024-04-17T17:36:47.125+0000] {taskinstance.py:2193} INFO - Starting attempt 2 of 4
[2024-04-17T17:36:47.136+0000] {taskinstance.py:2217} INFO - Executing <Task(PythonOperator): extract_data_from_csv> on 2024-04-17 17:31:37.009298+00:00
[2024-04-17T17:36:47.141+0000] {standard_task_runner.py:60} INFO - Started process 1713 to run task
[2024-04-17T17:36:47.143+0000] {standard_task_runner.py:87} INFO - Running: ['***', 'tasks', 'run', 'files_ext', 'extract_data_from_csv', 'manual__2024-04-17T17:31:37.009298+00:00', '--job-id', '2124', '--raw', '--subdir', 'DAGS_FOLDER/files_extraction.py', '--cfg-path', '/tmp/tmpggxi_uq5']
[2024-04-17T17:36:47.145+0000] {standard_task_runner.py:88} INFO - Job 2124: Subtask extract_data_from_csv
[2024-04-17T17:36:47.182+0000] {task_command.py:423} INFO - Running <TaskInstance: files_ext.extract_data_from_csv manual__2024-04-17T17:31:37.009298+00:00 [running]> on host fdd3cfdf3f53
[2024-04-17T17:36:47.240+0000] {taskinstance.py:2513} INFO - Exporting env vars: AIRFLOW_CTX_DAG_OWNER='***' AIRFLOW_CTX_DAG_ID='files_ext' AIRFLOW_CTX_TASK_ID='extract_data_from_csv' AIRFLOW_CTX_EXECUTION_DATE='2024-04-17T17:31:37.009298+00:00' AIRFLOW_CTX_TRY_NUMBER='2' AIRFLOW_CTX_DAG_RUN_ID='manual__2024-04-17T17:31:37.009298+00:00'
[2024-04-17T17:36:47.241+0000] {logging_mixin.py:188} INFO - /opt/***/dags/../extraction_done
[2024-04-17T17:36:47.253+0000] {taskinstance.py:2731} ERROR - Task failed with exception
Traceback (most recent call last):
  File "/home/airflow/.local/lib/python3.8/site-packages/airflow/models/taskinstance.py", line 444, in _execute_task
    result = _execute_callable(context=context, **execute_callable_kwargs)
  File "/home/airflow/.local/lib/python3.8/site-packages/airflow/models/taskinstance.py", line 414, in _execute_callable
    return execute_callable(context=context, **execute_callable_kwargs)
  File "/home/airflow/.local/lib/python3.8/site-packages/airflow/operators/python.py", line 200, in execute
    return_value = self.execute_callable()
  File "/home/airflow/.local/lib/python3.8/site-packages/airflow/operators/python.py", line 217, in execute_callable
    return self.python_callable(*self.op_args, **self.op_kwargs)
  File "/opt/airflow/dags/files_extraction.py", line 240, in extract_data_from_csv
    shutil.move(file_path, extraction_done_folder)
  File "/usr/local/lib/python3.8/shutil.py", line 789, in move
    raise Error("Destination path '%s' already exists" % real_dst)
shutil.Error: Destination path '/opt/***/dags/../extraction_done/vehicle-data.csv' already exists
[2024-04-17T17:36:47.261+0000] {taskinstance.py:1149} INFO - Marking task as UP_FOR_RETRY. dag_id=files_ext, task_id=extract_data_from_csv, execution_date=20240417T173137, start_date=20240417T173647, end_date=20240417T173647
[2024-04-17T17:36:47.269+0000] {standard_task_runner.py:107} ERROR - Failed to execute job 2124 for task extract_data_from_csv (Destination path '/opt/***/dags/../extraction_done/vehicle-data.csv' already exists; 1713)
[2024-04-17T17:36:47.276+0000] {local_task_job_runner.py:234} INFO - Task exited with return code 1
[2024-04-17T17:36:47.293+0000] {taskinstance.py:3312} INFO - 0 downstream tasks scheduled from follow-on schedule check
